2020-04-23 19:17:31,336 ERROR: Exception on /auth/reset_password_request [POST] [in /Library/Python/3.7/site-packages/flask/app.py:1891]
Traceback (most recent call last):
  File "/Library/Python/3.7/site-packages/flask/app.py", line 2446, in wsgi_app
    response = self.full_dispatch_request()
  File "/Library/Python/3.7/site-packages/flask/app.py", line 1951, in full_dispatch_request
    rv = self.handle_user_exception(e)
  File "/Library/Python/3.7/site-packages/flask/app.py", line 1820, in handle_user_exception
    reraise(exc_type, exc_value, tb)
  File "/Library/Python/3.7/site-packages/flask/_compat.py", line 39, in reraise
    raise value
  File "/Library/Python/3.7/site-packages/flask/app.py", line 1949, in full_dispatch_request
    rv = self.dispatch_request()
  File "/Library/Python/3.7/site-packages/flask/app.py", line 1935, in dispatch_request
    return self.view_functions[rule.endpoint](**req.view_args)
  File "/Users/normandieessig/Desktop/Thesis/Connect21/app/auth/routes.py", line 61, in reset_password_request
    send_password_reset_email(user)
  File "/Users/normandieessig/Desktop/Thesis/Connect21/app/auth/email.py", line 7, in send_password_reset_email
    token = user.get_reset_password_token()
  File "/Users/normandieessig/Desktop/Thesis/Connect21/app/models.py", line 59, in get_reset_password_token
    return jwt.encode(
NameError: name 'jwt' is not defined
2020-04-23 19:17:31,415 ERROR: Exception on /favicon.ico [GET] [in /Library/Python/3.7/site-packages/flask/app.py:1891]
Traceback (most recent call last):
  File "/Library/Python/3.7/site-packages/flask/app.py", line 1949, in full_dispatch_request
    rv = self.dispatch_request()
  File "/Library/Python/3.7/site-packages/flask/app.py", line 1925, in dispatch_request
    self.raise_routing_exception(req)
  File "/Library/Python/3.7/site-packages/flask/app.py", line 1907, in raise_routing_exception
    raise request.routing_exception
  File "/Library/Python/3.7/site-packages/flask/ctx.py", line 350, in match_request
    result = self.url_adapter.match(return_rule=True)
  File "/Library/Python/3.7/site-packages/werkzeug/routing.py", line 1799, in match
    raise NotFound()
werkzeug.exceptions.NotFound: 404 Not Found: The requested URL was not found on the server. If you entered the URL manually please check your spelling and try again.

During handling of the above exception, another exception occurred:

Traceback (most recent call last):
  File "/Library/Python/3.7/site-packages/flask/app.py", line 2446, in wsgi_app
    response = self.full_dispatch_request()
  File "/Library/Python/3.7/site-packages/flask/app.py", line 1951, in full_dispatch_request
    rv = self.handle_user_exception(e)
  File "/Library/Python/3.7/site-packages/flask/app.py", line 1815, in handle_user_exception
    return self.handle_http_exception(e)
  File "/Library/Python/3.7/site-packages/flask/app.py", line 1743, in handle_http_exception
    return handler(e)
  File "/Users/normandieessig/Desktop/Thesis/Connect21/app/errors/handlers.py", line 8, in not_found_error
    return render_template('errors/404.html'), 404
  File "/Library/Python/3.7/site-packages/flask/templating.py", line 140, in render_template
    ctx.app,
  File "/Library/Python/3.7/site-packages/flask/templating.py", line 120, in _render
    rv = template.render(context)
  File "/Library/Python/3.7/site-packages/jinja2/environment.py", line 1090, in render
    self.environment.handle_exception()
  File "/Library/Python/3.7/site-packages/jinja2/environment.py", line 832, in handle_exception
    reraise(*rewrite_traceback_stack(source=source))
  File "/Library/Python/3.7/site-packages/jinja2/_compat.py", line 28, in reraise
    raise value.with_traceback(tb)
  File "/Users/normandieessig/Desktop/Thesis/Connect21/app/templates/errors/404.html", line 1, in top-level template code
    {% extends "base.html" %}
  File "/Users/normandieessig/Desktop/Thesis/Connect21/app/templates/base.html", line 106, in top-level template code
    {% block content %}
  File "/Users/normandieessig/Desktop/Thesis/Connect21/app/templates/base.html", line 116, in block "content"
    {% block app_content %}
  File "/Users/normandieessig/Desktop/Thesis/Connect21/app/templates/errors/404.html", line 5, in block "app_content"
    <p><a href="{{ url_for('main.index') }}">Back</a></p>
  File "/Library/Python/3.7/site-packages/flask/helpers.py", line 370, in url_for
    return appctx.app.handle_url_build_error(error, endpoint, values)
  File "/Library/Python/3.7/site-packages/flask/app.py", line 2215, in handle_url_build_error
    reraise(exc_type, exc_value, tb)
  File "/Library/Python/3.7/site-packages/flask/_compat.py", line 39, in reraise
    raise value
  File "/Library/Python/3.7/site-packages/flask/helpers.py", line 358, in url_for
    endpoint, values, method=method, force_external=external
  File "/Library/Python/3.7/site-packages/werkzeug/routing.py", line 2020, in build
    raise BuildError(endpoint, values, method, self)
werkzeug.routing.BuildError: Could not build url for endpoint 'main.index'. Did you mean 'main.explore' instead?
2020-04-24 12:22:58,778 INFO: Connect21 startup [in /Users/normandieessig/Desktop/Thesis/Connect21/app/__init__.py:75]
